<?xml version="1.0" ?>
<!-- =================================================================================== -->
<!-- |    This document was autogenerated by xacro from motopos_d500.xacro             | -->
<!-- |    EDITING THIS FILE BY HAND IS NOT RECOMMENDED                                 | -->
<!-- =================================================================================== -->
<robot name="motoman_motopos_d500">
  <!-- Properties -->
  <material name="yaskawa_blue">
    <color rgba="0.12941 0.14902 0.74902 1"/>
  </material>
  <!-- link list -->
  <link name="base_link">
    <visual>
      <geometry>
        <mesh filename="package://motoman_motopos_d500_support/meshes/motopos_d500/visual/base_link.stl"/>
      </geometry>
      <material name="">
        <color rgba="0.12941176470588237 0.14901960784313725 0.7490196078431373 1.0"/>
      </material>
    </visual>
    <collision>
      <geometry>
        <mesh filename="package://motoman_motopos_d500_support/meshes/motopos_d500/collision/base_link.stl"/>
      </geometry>
    </collision>
  </link>
  <link name="link_1">
    <visual>
      <geometry>
        <mesh filename="package://motoman_motopos_d500_support/meshes/motopos_d500/visual/link_1.stl"/>
      </geometry>
      <material name="">
        <color rgba="0.12941176470588237 0.14901960784313725 0.7490196078431373 1.0"/>
      </material>
    </visual>
    <collision>
      <geometry>
        <mesh filename="package://motoman_motopos_d500_support/meshes/motopos_d500/collision/link_1.stl"/>
      </geometry>
    </collision>
  </link>
  <link name="link_2">
    <visual>
      <geometry>
        <mesh filename="package://motoman_motopos_d500_support/meshes/motopos_d500/visual/link_2.stl"/>
      </geometry>
      <material name="">
        <color rgba="0.12941176470588237 0.14901960784313725 0.7490196078431373 1.0"/>
      </material>
    </visual>
    <collision>
      <geometry>
        <mesh filename="package://motoman_motopos_d500_support/meshes/motopos_d500/collision/link_2.stl"/>
      </geometry>
    </collision>
  </link>
  <!-- end of link list -->
  <!-- joint list -->
  <joint name="joint_1" type="revolute">
    <parent link="base_link"/>
    <child link="link_1"/>
    <origin rpy="0 0 0" xyz="0 0 0.380"/>
    <axis xyz="0 -1 0"/>
    <limit effort="1274" lower="-2.3561" upper="2.3561" velocity="1.3962"/>
  </joint>
  <joint name="joint_2" type="revolute">
    <parent link="link_1"/>
    <child link="link_2"/>
    <origin rpy="0 0 0" xyz="0 0 0"/>
    <axis xyz="0 0 -1"/>
    <limit effort="392" lower="-3.4906" upper="3.4906" velocity="2.7925"/>
  </joint>
  <!-- end of joint list -->
  <!-- ROS base_link to Robot Manufacturer World Coordinates transform -->
  <link name="base"/>
  <joint name="base_link-base" type="fixed">
    <origin rpy="0 0 0" xyz="0 0 0.380"/>
    <parent link="base_link"/>
    <child link="base"/>
  </joint>
  <!-- ROS-Industrial 'tool0' frame: all-zeros tool frame -->
  <link name="tool0"/>
  <joint name="joint_2-tool0" type="fixed">
    <origin rpy="0 0 0" xyz="0 0 0.150 "/>
    <parent link="link_2"/>
    <child link="tool0"/>
  </joint>
</robot>

