<?xml version="1.0" ?>
<!-- =================================================================================== -->
<!-- |    This document was autogenerated by xacro from ma2010.xacro                   | -->
<!-- |    EDITING THIS FILE BY HAND IS NOT RECOMMENDED                                 | -->
<!-- =================================================================================== -->
<robot name="combined">
  <!--robots pose-->
  <link name="world"/>

  <joint name="MA2010_pose" type="fixed">
    <parent link="world"/>
    <child link="MA2010_base_link"/>
    <origin rpy="0.0 0.0 0.0" xyz="0.0 0 0.762"/><!--MA2010 pedestal-->
  </joint>

  <joint name="D500B_pose" type="fixed">
    <parent link="world"/>
    <child link="D500B_base_link"/>
    <origin rpy="0.0 -0.261799 -1.5708" xyz="1.6438 -0.911639 0.472054"/><!--D500B pedestal-->
  </joint>

  <joint name="MA1440_pose" type="fixed">
    <parent link="world"/>
    <child link="MA1440_base_link"/>
    <origin rpy="0.0 0.0 3.14159" xyz="2.689552 -0.39515 0.908"/><!--MA1440 pedestal-->
  </joint>

  <link name="Ground">
    <visual>
      <geometry>
        <box size="4.953 6.4 0.01"/>
      </geometry>
      <material name="">
        <color rgba="0.1490196078431373 0.14901960784313725 0.72941176470588237 1.0"/>
      </material>
    </visual>
    <collision>
      <geometry>
        <box size="4.953 6.4 0.01"/>
      </geometry>
    </collision>
  </link>
  <joint name="Ground_pose" type="fixed">
    <parent link="world"/>
    <child link="Ground"/>
    <origin rpy="0.0 0.0 0" xyz="1.3462 0 -0.005"/>
  </joint>


  <!-- MA2010 list -->
  <link name="MA2010_pedestal">
    <visual>
      <geometry>
        <box size="0.55 0.6858 0.762"/>
      </geometry>
      <material name="">
        <color rgba="0.12941176470588237 0.14901960784313725 0.7490196078431373 1.0"/>
      </material>
    </visual>
    <collision>
      <geometry>
        <box size="0.55 0.6858 0.762"/>        
      </geometry>
    </collision>
  </link>

  <link name="MA2010_base_link">
    <visual>
      <geometry>
        <mesh filename="model://MA_2010_A0/meshes/visual/base_link.stl"/>
      </geometry>
      <material name="">
        <color rgba="0.12941176470588237 0.14901960784313725 0.7490196078431373 1.0"/>
      </material>
    </visual>
    <collision>
      <geometry>
        <mesh filename="model://MA_2010_A0/meshes/collision/base_link.stl"/>
      </geometry>
    </collision>
  </link>
  <link name="MA2010_link_1_s">
    <visual>
      <geometry>
        <mesh filename="model://MA_2010_A0/meshes/visual/link_1_s.stl"/>
      </geometry>
      <material name="">
        <color rgba="0.12941176470588237 0.14901960784313725 0.7490196078431373 1.0"/>
      </material>
    </visual>
    <collision>
      <geometry>
        <mesh filename="model://MA_2010_A0/meshes/collision/link_1_s.stl"/>
      </geometry>
    </collision>
  </link>
  <link name="MA2010_link_2_l">
    <visual>
      <geometry>
        <mesh filename="model://MA_2010_A0/meshes/visual/link_2_l.stl"/>
      </geometry>
      <material name="">
        <color rgba="0.12941176470588237 0.14901960784313725 0.7490196078431373 1.0"/>
      </material>
    </visual>
    <collision>
      <geometry>
        <mesh filename="model://MA_2010_A0/meshes/collision/link_2_l.stl"/>
      </geometry>
    </collision>
  </link>
  <link name="MA2010_link_3_u">
    <visual>
      <geometry>
        <mesh filename="model://MA_2010_A0/meshes/visual/link_3_u.stl"/>
      </geometry>
      <material name="">
        <color rgba="0.12941176470588237 0.14901960784313725 0.7490196078431373 1.0"/>
      </material>
    </visual>
    <collision>
      <geometry>
        <mesh filename="model://MA_2010_A0/meshes/collision/link_3_u.stl"/>
      </geometry>
    </collision>
  </link>
  <link name="MA2010_link_4_r">
    <visual>
      <geometry>
        <mesh filename="model://MA_2010_A0/meshes/visual/link_4_r.stl"/>
      </geometry>
      <material name="">
        <color rgba="0.12941176470588237 0.14901960784313725 0.7490196078431373 1.0"/>
      </material>
    </visual>
    <collision>
      <geometry>
        <mesh filename="model://MA_2010_A0/meshes/collision/link_4_r.stl"/>
      </geometry>
    </collision>
  </link>
  <link name="MA2010_link_5_b">
    <visual>
      <geometry>
        <mesh filename="model://MA_2010_A0/meshes/visual/link_5_b.stl"/>
      </geometry>
      <material name="">
        <color rgba="0.12941176470588237 0.14901960784313725 0.7490196078431373 1.0"/>
      </material>
    </visual>
    <collision>
      <geometry>
        <mesh filename="model://MA_2010_A0/meshes/collision/link_5_b.stl"/>
      </geometry>
    </collision>
  </link>
  <link name="MA2010_link_6_t">
    <visual>
      <geometry>
        <mesh filename="model://MA_2010_A0/meshes/visual/link_6_t.stl"/>
      </geometry>
      <material name="">
        <color rgba="0.12941176470588237 0.14901960784313725 0.7490196078431373 1.0"/>
      </material>
    </visual>
    <collision>
      <geometry>
        <mesh filename="model://MA_2010_A0/meshes/collision/link_6_t.stl"/>
      </geometry>
    </collision>
  </link>

  <link name="MA2010_filler">
    <visual>
      <geometry>
        <box size="0.4 0.2 0.3"/>
      </geometry>
      <material name="">
        <color rgba="0.72941176470588237 0.14901960784313725 0.1490196078431373 1.0"/>
      </material>
    </visual>
    <collision>
      <geometry>
        <box size="0.3 0.5 0.3"/>
      </geometry>
    </collision>
  </link>


  <!-- end of link list -->
  <!-- joint list -->
  <joint name="MA2010_joint_1_s" type="revolute">
    <parent link="MA2010_base_link"/>
    <child link="MA2010_link_1_s"/>
    <origin rpy="0 0 0" xyz="0 0 0.505"/>
    <axis xyz="0 0 1"/>
    <limit effort="3087" lower="-3.1416" upper="3.1416" velocity="3.4383"/>
  </joint>
  <joint name="MA2010_joint_2_l" type="revolute">
    <parent link="MA2010_link_1_s"/>
    <child link="MA2010_link_2_l"/>
    <origin rpy="0 0 0" xyz="0.150 0 0"/>
    <axis xyz="0 1 0"/>
    <limit effort="2744" lower="-1.8326" upper="2.7052" velocity="3.3161"/>
  </joint>
  <joint name="MA2010_joint_3_u" type="revolute">
    <parent link="MA2010_link_2_l"/>
    <child link="MA2010_link_3_u"/>
    <origin rpy="0 0 0" xyz="0 0 0.760"/>
    <axis xyz="0 -1 0"/>
    <limit effort="874.65" lower="-1.5009" upper="2.7925" velocity="3.6652"/>
  </joint>
  <joint name="MA2010_joint_4_r" type="revolute">
    <parent link="MA2010_link_3_u"/>
    <child link="MA2010_link_4_r"/>
    <origin rpy="0 0 0" xyz="0 0 0.200"/>
    <axis xyz="-1 0 0"/>
    <limit effort="78.4" lower="-2.6180" upper="2.6180" velocity="7.1558"/>
  </joint>
  <joint name="MA2010_joint_5_b" type="revolute">
    <parent link="MA2010_link_4_r"/>
    <child link="MA2010_link_5_b"/>
    <origin rpy="0 0 0" xyz="1.082 0 0"/>
    <axis xyz="0 -1 0"/>
    <limit effort="59.58" lower="-2.3562" upper="1.5708" velocity="7.1558"/>
  </joint>
  <joint name="MA2010_joint_6_t" type="revolute">
    <parent link="MA2010_link_5_b"/>
    <child link="MA2010_link_6_t"/>
    <origin rpy="0 0 0" xyz="0 0 0"/>
    <axis xyz="-1 0 0"/>
    <limit effort="29.6" lower="-3.6652" upper="3.6652" velocity="10.6465"/>
  </joint>
  <joint name="MA2010_joint_pedestal" type="fixed">
    <parent link="MA2010_base_link"/>
    <child link="MA2010_pedestal"/>
    <origin rpy="0 0 0" xyz="0 0 -0.381"/>
    <axis xyz="0 0 1"/>
  </joint>
  <!-- end of joint list -->
  <joint name="filler_joint" type="fixed">
    <parent link="MA2010_link_2_l"/>
    <child link="MA2010_filler"/>
    <origin rpy="0 0 0" xyz="0.0 -0.36 0.4"/>
    <axis xyz="0 0 0"/>
  </joint>
  <link name="torch">
    <visual>
      <geometry>
        <mesh filename="model://MA_2010_A0/meshes/visual/torch.stl" scale="0.001 0.001 0.001"/>
      </geometry>
      <material name="">
        <color rgba="0.12941176470588237 0.88 0.7490196078431373 1.0"/>
      </material>
    </visual>
    <collision>
      <geometry>
        <mesh filename="model://MA_2010_A0/meshes/collision/torch.stl" scale="0.001 0.001 0.001"/>
      </geometry>
    </collision>
  </link>
  <joint name="torch_joint" type="fixed">
    <parent link="MA2010_link_6_t"/>
    <child link="torch"/>
    <origin rpy="0 1.57 0" xyz="0.1 0 0"/>
    <axis xyz="0 0 0"/>
  </joint>




  <!-- D500B URDF -->
  <material name="yaskawa_blue">
    <color rgba="0.12941 0.14902 0.74902 1"/>
  </material>
  <!-- link list -->
  <link name="D500B_base_link">
    <visual>
      <geometry>
        <mesh filename="model://D500B/meshes/visual/base_link.stl"/>
      </geometry>
      <material name="">
        <color rgba="0.12941176470588237 0.14901960784313725 0.7490196078431373 1.0"/>
      </material>
    </visual>
    <collision>
      <geometry>
        <mesh filename="model://D500B/meshes/collision/base_link.stl"/>
      </geometry>
    </collision>
  </link>
  <link name="D500B_link_1">
    <visual>
      <geometry>
        <mesh filename="model://D500B/meshes/visual/link_1.stl"/>
      </geometry>
      <material name="">
        <color rgba="0.12941176470588237 0.14901960784313725 0.7490196078431373 1.0"/>
      </material>
    </visual>
    <collision>
      <geometry>
        <mesh filename="model://D500B/meshes/collision/link_1.stl"/>
      </geometry>
    </collision>
  </link>
  <link name="D500B_link_2">
    <visual>
      <geometry>
        <mesh filename="model://D500B/meshes/visual/link_2.stl"/>
      </geometry>
      <material name="">
        <color rgba="0.12941176470588237 0.14901960784313725 0.7490196078431373 1.0"/>
      </material>
    </visual>
    <collision>
      <geometry>
        <mesh filename="model://D500B/meshes/collision/link_2.stl"/>
      </geometry>
    </collision>
  </link>
  <!-- end of link list -->
  <!-- joint list -->
  <joint name="D500B_joint_1" type="revolute">
    <parent link="D500B_base_link"/>
    <child link="D500B_link_1"/>
    <origin rpy="0 0 0" xyz="0 0 0.380"/>
    <axis xyz="0 -1 0"/>
    <limit effort="1274" lower="-2.3561" upper="2.3561" velocity="1.3962"/>
  </joint>
  <joint name="D500B_joint_2" type="revolute">
    <parent link="D500B_link_1"/>
    <child link="D500B_link_2"/>
    <origin rpy="0 0 0" xyz="0 0 0"/>
    <axis xyz="0 0 -1"/>
    <limit effort="392" lower="-3.4906" upper="3.4906" velocity="2.7925"/>
  </joint>
  <!-- end of joint list -->

  <!-- MA1440 ROBOT URDF -->
  <link name="MA1440_pedestal">
    <visual>
      <geometry>
        <mesh filename="model://objects/meshes/ma1440_pedestal.stl" scale="0.001 0.001 0.001"/>
      </geometry>
      <material name="">
        <color rgba="0.12941176470588237 0.14901960784313725 0.7490196078431373 1.0"/>
      </material>
    </visual>
    <collision>
      <geometry>
        <mesh filename="model://objects/meshes/ma1440_pedestal.stl" scale="0.001 0.001 0.001"/>
      </geometry>
    </collision>
  </link>
  <link name="MA1440_base_link">
    <visual>
      <geometry>
        <mesh filename="model://MA_1440_A0/meshes/visual/base_link.stl"/>
      </geometry>
      <material name="">
        <color rgba="0.12941176470588237 0.14901960784313725 0.7490196078431373 1.0"/>
      </material>
    </visual>
    <collision>
      <geometry>
        <mesh filename="model://MA_1440_A0/meshes/collision/base_link.stl"/>
      </geometry>
    </collision>
  </link>
  <link name="MA1440_link_1_s">
    <visual>
      <geometry>
        <mesh filename="model://MA_1440_A0/meshes/visual/link_1_s.stl"/>
      </geometry>
      <material name="">
        <color rgba="0.12941176470588237 0.14901960784313725 0.7490196078431373 1.0"/>
      </material>
    </visual>
    <collision>
      <geometry>
        <mesh filename="model://MA_1440_A0/meshes/collision/link_1_s.stl"/>
      </geometry>
    </collision>
  </link>
  <link name="MA1440_link_2_l">
    <visual>
      <geometry>
        <mesh filename="model://MA_1440_A0/meshes/visual/link_2_l.stl"/>
      </geometry>
      <material name="">
        <color rgba="0.12941176470588237 0.14901960784313725 0.7490196078431373 1.0"/>
      </material>
    </visual>
    <collision>
      <geometry>
        <mesh filename="model://MA_1440_A0/meshes/collision/link_2_l.stl"/>
      </geometry>
    </collision>
  </link>
  <link name="MA1440_link_3_u">
    <visual>
      <geometry>
        <mesh filename="model://MA_1440_A0/meshes/visual/link_3_u.stl"/>
      </geometry>
      <material name="">
        <color rgba="0.12941176470588237 0.14901960784313725 0.7490196078431373 1.0"/>
      </material>
    </visual>
    <collision>
      <geometry>
        <mesh filename="model://MA_1440_A0/meshes/collision/link_3_u.stl"/>
      </geometry>
    </collision>
  </link>
  <link name="MA1440_link_4_r">
    <visual>
      <geometry>
        <mesh filename="model://MA_1440_A0/meshes/visual/link_4_r.stl"/>
      </geometry>
      <material name="">
        <color rgba="0.12941176470588237 0.14901960784313725 0.7490196078431373 1.0"/>
      </material>
    </visual>
    <collision>
      <geometry>
        <mesh filename="model://MA_1440_A0/meshes/collision/link_4_r.stl"/>
      </geometry>
    </collision>
  </link>
  <link name="MA1440_link_5_b">
    <visual>
      <geometry>
        <mesh filename="model://MA_1440_A0/meshes/visual/link_5_b.stl"/>
      </geometry>
      <material name="">
        <color rgba="0.12941176470588237 0.14901960784313725 0.7490196078431373 1.0"/>
      </material>
    </visual>
    <collision>
      <geometry>
        <mesh filename="model://MA_1440_A0/meshes/collision/link_5_b.stl"/>
      </geometry>
    </collision>
  </link>
  <link name="MA1440_link_6_t">
    <visual>
      <geometry>
        <mesh filename="model://MA_1440_A0/meshes/visual/link_6_t.stl"/>
      </geometry>
      <material name="">
        <color rgba="0.12941176470588237 0.14901960784313725 0.7490196078431373 1.0"/>
      </material>
    </visual>
    <collision>
      <geometry>
        <mesh filename="model://MA_1440_A0/meshes/collision/link_6_t.stl"/>
      </geometry>
    </collision>
  </link>
  <!-- end of link list -->
  <!-- joint list -->
  <joint name="MA1440_joint_pedestal" type="fixed">
    <parent link="MA1440_base_link"/>
    <child link="MA1440_pedestal"/>
    <origin rpy="0 0 0" xyz="0 0 -0.908"/>
    <axis xyz="0 0 1"/>
  </joint>

  <joint name="MA1440_joint_1_s" type="revolute">
    <parent link="MA1440_base_link"/>
    <child link="MA1440_link_1_s"/>
    <origin rpy="0 0 0" xyz="0 0 0.450"/>
    <axis xyz="0 0 1"/>
    <limit effort="648.27" lower="-2.9670" upper="2.9670" velocity="3.8397"/>
  </joint>
  <joint name="MA1440_joint_2_l" type="revolute">
    <parent link="MA1440_link_1_s"/>
    <child link="MA1440_link_2_l"/>
    <origin rpy="0 0 0" xyz="0.155 0 0"/>
    <axis xyz="0 1 0"/>
    <limit effort="874.65" lower="-1.5708" upper="2.7052" velocity="3.4906"/>
  </joint>
  <joint name="MA1440_joint_3_u" type="revolute">
    <parent link="MA1440_link_2_l"/>
    <child link="MA1440_link_3_u"/>
    <origin rpy="0 0 0" xyz="0 0 0.614"/>
    <axis xyz="0 -1 0"/>
    <limit effort="257.25" lower="-1.4835" upper="2.6179" velocity="3.8397"/>
  </joint>
  <joint name="MA1440_joint_4_r" type="revolute">
    <parent link="MA1440_link_3_u"/>
    <child link="MA1440_link_4_r"/>
    <origin rpy="0 0 0" xyz="0.640 0 0.200"/>
    <axis xyz="-1 0 0"/>
    <limit effort="74.97" lower="-3.1415" upper="3.1415" velocity="7.1558"/>
  </joint>
  <joint name="MA1440_joint_5_b" type="revolute">
    <parent link="MA1440_link_4_r"/>
    <child link="MA1440_link_5_b"/>
    <origin rpy="0 0 0" xyz="0 0 0"/>
    <axis xyz="0 -1 0"/>
    <limit effort="44.69" lower="-2.3562" upper="2.3562" velocity="7.1558"/>
  </joint>
  <joint name="MA1440_joint_6_t" type="revolute">
    <parent link="MA1440_link_5_b"/>
    <child link="MA1440_link_6_t"/>
    <origin rpy="0 0 0" xyz="0 0 0"/>
    <axis xyz="-1 0 0"/>
    <limit effort="14.80" lower="-6.2832" upper="6.2832" velocity="10.6465"/>
  </joint>

  <link name="flir_mti">
    <visual>
      <geometry>
        <mesh filename="model://MA_1440_A0/meshes/visual/flir_mti.stl" scale="0.001 0.001 0.001"/>
      </geometry>
      <material name="">
        <color rgba="0.12941176470588237 0.88 0.7490196078431373 1.0"/>
      </material>
    </visual>
    <collision>
      <geometry>
        <mesh filename="model://MA_1440_A0/meshes/collision/flir_mti.stl" scale="0.001 0.001 0.001"/>
      </geometry>
    </collision>
  </link>
  <joint name="flir_mti_joint" type="fixed">
    <parent link="MA1440_link_6_t"/>
    <child link="flir_mti"/>
    <origin rpy="-1.57 0 3.14149" xyz="0.08 0.04 -0.04"/>
    <axis xyz="0 0 0"/>
  </joint>



  <!--objects list -->
  <!--Controller Box-->
  <link name="Controller">
    <visual>
      <geometry>
        <mesh filename="model://objects/meshes/controller.stl" scale="0.001 0.001 0.001"/>
      </geometry>
      <material name="">
        <color rgba="0.72941176470588237 0.14901960784313725 0.1490196078431373 1.0"/>
      </material>
    </visual>
    <collision>
      <geometry>
        <mesh filename="model://objects/meshes/controller.stl" scale="0.001 0.001 0.001"/>
      </geometry>
    </collision>
  </link>
  <joint name="Controller_pose" type="fixed">
    <parent link="world"/>
    <child link="Controller"/>
    <origin rpy="0.0 0.0 1.57" xyz="-1.4192 -0.1595 0.0"/>
  </joint>


  <!--Wall Box-->
  <link name="Wall">
    <visual>
      <geometry>
        <box size="0.6096 1.0668 5"/>
      </geometry>
      <material name="">
        <color rgba="0.72941176470588237 0.14901960784313725 0.1490196078431373 1.0"/>
      </material>
    </visual>
    <collision>
      <geometry>
        <box size="0.6096 1.0668 5"/>
      </geometry>
    </collision>
  </link>
  <joint name="Wall_pose" type="fixed">
    <parent link="world"/>
    <child link="Wall"/>
    <origin rpy="0.0 0.0 1.57" xyz="-0.0908 2.0574 2.5"/>
  </joint>

  <!--Tabel1 Box-->
  <link name="Tabel1">
    <visual>
      <geometry>
        <box size="0.76 1.22 1.3"/>
      </geometry>
      <material name="">
        <color rgba="0.72941176470588237 0.14901960784313725 0.1490196078431373 1.0"/>
      </material>
    </visual>
    <collision>
      <geometry>
        <box size="0.76 1.22 1.3"/>
      </geometry>
    </collision>
  </link>
  <joint name="Tabel1_pose" type="fixed">
    <parent link="world"/>
    <child link="Tabel1"/>
    <origin rpy="0.0 0.0 1.57" xyz="-0.0891 -2.0584 0.65"/>
  </joint>



    <!--Table2 Box-->
  <link name="Table2">
    <visual>
      <geometry>
        <box size="0.6 1.2 0.87"/>
      </geometry>
      <material name="">
        <color rgba="0.72941176470588237 0.14901960784313725 0.1490196078431373 1.0"/>
      </material>
    </visual>
    <collision>
      <geometry>
        <box size="0.6 1.2 0.87"/>
      </geometry>
    </collision>
  </link>
  <joint name="Table2_pose" type="fixed">
    <parent link="world"/>
    <child link="Table2"/>
    <origin rpy="0.0 0.0 1.57" xyz="2.9159 -2.1384 0.435"/>
  </joint>

    <!--Welder Box-->
  <link name="Welder">
    <visual>
      <geometry>
        <box size="0.94 0.32 1.2446"/>
      </geometry>
      <material name="">
        <color rgba="0.72941176470588237 0.14901960784313725 0.1490196078431373 1.0"/>
      </material>
    </visual>
    <collision>
      <geometry>
        <box size="0.94 0.32 1.2446"/>
      </geometry>
    </collision>
  </link>
  <joint name="Welder_pose" type="fixed">
    <parent link="world"/>
    <child link="Welder"/>
    <origin rpy="0.0 0.0 0" xyz="-0.195 -0.6807 0.6223"/>
  </joint>

    <!--Shelf Box-->
  <link name="Shelf">
    <visual>
      <geometry>
        <box size="0.8128 0.4699 0.820"/>
      </geometry>
      <material name="">
        <color rgba="0.72941176470588237 0.14901960784313725 0.1490196078431373 1.0"/>
      </material>
    </visual>
    <collision>
      <geometry>
        <box size="0.8128 0.4699 0.820"/>
      </geometry>
    </collision>
  </link>
  <joint name="Shelf_pose" type="fixed">
    <parent link="world"/>
    <child link="Shelf"/>
    <origin rpy="0.0 0.0 0" xyz="1.69 1.77165 0.41"/>
  </joint>

  <!--Passive Box-->
  <link name="Passive">
    <visual>
      <geometry>
        <box size="0.45 0.41 0.95"/>
      </geometry>
      <material name="">
        <color rgba="0.72941176470588237 0.14901960784313725 0.1490196078431373 1.0"/>
      </material>
    </visual>
    <collision>
      <geometry>
        <box size="0.45 0.41 0.95"/>
      </geometry>
    </collision>
  </link>
  <joint name="Passive_pose" type="fixed">
    <parent link="world"/>
    <child link="Passive"/>
    <origin rpy="0.0 0.0 0" xyz="1.661 1.2047 0.475"/>
  </joint>

  <!--Control Panel Box-->
  <link name="ControlPanel">
    <visual>
      <geometry>
        <box size="0.46 0.46 1.11"/>
      </geometry>
      <material name="">
        <color rgba="0.72941176470588237 0.14901960784313725 0.1490196078431373 1.0"/>
      </material>
    </visual>
    <collision>
      <geometry>
        <box size="0.46 0.46 1.11"/>
      </geometry>
    </collision>
  </link>
  <joint name="ControlPanel_pose" type="fixed">
    <parent link="world"/>
    <child link="ControlPanel"/>
    <origin rpy="0.0 0.0 0.0" xyz="1.0536 1.65397 0.555"/>
  </joint>
</robot>

